Exception on / [GET]
Traceback (most recent call last):
  File "D:\Python\Scripts\env\lib\site-packages\flask\app.py", line 1982, in wsgi_app
    response = self.full_dispatch_request()
  File "D:\Python\Scripts\env\lib\site-packages\flask\app.py", line 1614, in full_dispatch_request
    rv = self.handle_user_exception(e)
  File "D:\Python\Scripts\env\lib\site-packages\flask\app.py", line 1517, in handle_user_exception
    reraise(exc_type, exc_value, tb)
  File "D:\Python\Scripts\env\lib\site-packages\flask\_compat.py", line 33, in reraise
    raise value
  File "D:\Python\Scripts\env\lib\site-packages\flask\app.py", line 1612, in full_dispatch_request
    rv = self.dispatch_request()
  File "D:\Python\Scripts\env\lib\site-packages\flask\app.py", line 1598, in dispatch_request
    return self.view_functions[rule.endpoint](**req.view_args)
  File "helloWorld.py", line 17, in hello_world
    client = language.LanguageServiceClient()
  File "D:\Python\Scripts\env\lib\site-packages\google\cloud\language_v1\gapic\language_service_client.py", line 132, in __init__
    ssl_credentials=ssl_credentials)
  File "D:\Python\Scripts\env\lib\site-packages\google\gax\grpc.py", line 106, in create_stub
    credentials = _grpc_google_auth.get_default_credentials(scopes)
  File "D:\Python\Scripts\env\lib\site-packages\google\gax\_grpc_google_auth.py", line 62, in get_default_credentials
    credentials, _ = google.auth.default(scopes=scopes)
  File "D:\Python\Scripts\env\lib\site-packages\google\auth\_default.py", line 281, in default
    credentials, project_id = checker()
  File "D:\Python\Scripts\env\lib\site-packages\google\auth\_default.py", line 142, in _get_explicit_environ_credentials
    os.environ[environment_vars.CREDENTIALS])
  File "D:\Python\Scripts\env\lib\site-packages\google\auth\_default.py", line 65, in _load_credentials_from_file
    'File {} was not found.'.format(filename))
google.auth.exceptions.DefaultCredentialsError: File "D:\Coding\stockSense\Whatever-21592b267981.json" was not found.
